Workbook

Sheet Boshlash
A1: CHIQUVCHI ADMIN KPI VA OYLIK
B5: BONUS UCHTA QISMDAN IBORAT
B6: Chiquvchi adminning ishi faqat uzaytirish emas. Uning asosiy qiymati — BUTUN MAVJUD BAZANI saqlab turishida. Shuning uchun bonus uchta manbadan yig'iladi va har biri boshqa xatti-harakatni rag'batlantiradi.
B7: BONUS A — Ushlab qolish | C7: Oy oxiridagi har bir faol o'quvchi uchun 6 000 so'm, ketish foiziga qarab ko'paytiriladi. Bu bonusning eng katta qismi. Mantiq: admin bazani qanchalik to'liq saqlasa, shuncha ko'p oladi.
B8: BONUS B — Uzaytirish | C8: Kursi tugab keyingi bosqichga o'tgan har bir o'quvchi uchun 45 000 so'm. Bu — aniq yutuq uchun mukofot.
B9: BONUS C — Qarzdorlik | C9: Oy davomida yig'ilgan qarz summasining 1% i.
B10: NEGA AYNAN SHUNDAY BO'LINDI
C11: Agar butun bonus faqat uzaytirishga bog'lansa, bitta uzaytirish uchun 120–150 ming so'm to'lash kerak bo'lardi — bu bitta o'quvchidan qoladigan oylik margindan (200–250 ming) juda katta ulush. Bonusni bazaga tarqatsak, har bir o'quvchi uchun 6 000 so'm chiqadi — bu marginning atigi 2.5–3% i.
C12: Yana bir sabab: uzaytirish oyning oxirgi haftasidagi ish. Ushlab qolish esa HAR KUNGI ish — davomad, kelmaganga xabar, muammoni erta ko'rish. Bonusning katta qismi kundalik ishga bog'langani to'g'ri.
B13: Pagelаr
B14: KPI qoidalari | C14: Formula, doimiy qiymatlar va uchta koeffitsient jadvali. Bu — qonun matni.
B15: KALKULYATOR | C15: ASOSIY VARAQ. Sariq katakchalarga oy oxiridagi haqiqiy raqamlarni kiritasiz.
B16: Ssenariylar | C16: 6 xil oy yonma-yon.
B17: Birlik iqtisodiyoti | C17: Bonus markaz marginidan qancha ulush olishi — tekshiruv hisobi.
B18: Vazifa va KPI | C18: Har bir kundalik vazifa qaysi KPI'ga va qaysi audit mezoniga ulanishi.
B19: ASOSIY FORMULA
C20: OYLIK = Oklad + ( Bonus A + Bonus B + Bonus C ) × Samaradorlik koeffitsienti − Jarimalar
B21: RANGLAR
B22: Sariq fon, ko'k raqam | C22: Ruchnoy to'ldirilishi kerak
B23: Oq fon, qora raqam | C23: Avtomatik hisoblaydi
B24: Kulrang fon | C24: Doimiy qiymat. O'zgartirish rahbar qarori bilan.
B25: OGOHLANTIRISH
C26: Bu shkala — GIPOTEZA. Hozir bizda ketish foizi ham, uzaytirish konversiyasi ham o'lchanmagan. Birinchi 2 oy o'lchaymiz va kafolatlangan minimum to'laymiz, keyin shkalani bir marta qayta sozlaymiz.
C27: MUHIM: Bonus A faol o'quvchi soniga bog'liq. Agar hozirgi baza 320 dan sezilarli kam bo'lsa, Birlik iqtisodiyoti pagedagi tekshiruvni albatta bajarish kerak - 1 o'quvchiga to'g'ri keladigan summani o'zgartirish kerak bo'lishi mumkin.

Sheet KPI qoidalari
A1: KPI QOIDALARI VA KOEFFITSIENTLAR KALKULYATOR shu pagedagi raqamlarni oladi
A5: A. ASOSIY FORMULA
B6: OYLIK = Oklad + ( A: Faol o'quvchi × 6 000 × Ushlab qolish koef + B: Uzaytirgan × 45 000 × Uzaytirish koef + C: Yig'ilgan qarz × 1% ) × Samaradorlik koef − Jarimalar
A8: B. DOIMIY QIYMATLAR
B9: Oklad | C9: 3000000 | F9: Kundalik nazorat, xona, davomad, o'qituvchilarga yordam — jarayon ishi.
B10: BONUS A - 1 ta faol o'quvchi uchun | C10: 1000 | F10: Oy oxiridagi faol o'quvchi soniga ko'paytiriladi.
B11: BONUS B - 1 ta uzaytirgan o'quvchi uchun | C11: 35000 | F11: Kurs bosqichi tugab, keyingisiga o'tganlar. Yangi kurslar sotgan qo'shimcha
B12: BONUS C - yig'ilgan qarzdan foiz | C12: 0.01 | F12: Yig'ish 80% dan past bo'lsa — yarmi.
B13: Sababi aniqlanmagan ketish - 1 tasi | C13: 50000 | F13: Har bir ketgan o'quvchining sababi yozilishi SHART.
B14: Tiket jarimasi - 1 tasi | C14: 50000 | F14: Kundalik nazorat standartlari buzilgani uchun.
B15: Kafolatlangan minimum (1–2 oy) | C15: 4500000 | F15: Kalibrovka davrida.
B16: Oylik yuqori chegara | C16: 7500000 | F16: Bundan yuqorisi rahbar tasdig'i bilan to'lanadi.
A17: C. USHLAB QOLISH KOEFFITSIENTI — oylik ketish foizi bo'yicha (Bonus A ga)
B18: Quyi chegara | C18: Yuqori chegara | D18: KOEFFITSIENT | F18: Izoh
B19: 0 | C19: 0.0399 | D19: 1.15 | F19: Ajoyib. Baza deyarli to'liq saqlangan.
B20: 0.04 | C20: 0.0599 | D20: 1.1 | F20: Normadan yaxshi.
B21: 0.06 | C21: 0.0799 | D21: 1 | F21: NORMA. Bonus to'liq.
B22: 0.08 | C22: 0.0999 | D22: 0.8 | F22: Normadan yomon.
B23: 0.1 | C23: 0.1199 | D23: 0.6 | F23: Jiddiy muammo.
B24: 0.12 | C24: 1 | D24: 0.4 | F24: Baza oqib ketyapti.
A25: D. UZAYTIRISH KOEFFITSIENTI — kursi tugaganlarning qanchasi boshqa kursda o'qidi
B26: Quyi chegara | C26: Yuqori chegara | D26: KOEFFITSIENT | F26: Izoh
B27: 0 | C27: 0.5499 | D27: 0.5 | F27: Normadan keskin past.
B28: 0.55 | C28: 0.6499 | D28: 0.8 | F28: Minimal chegara.
B29: 0.65 | C29: 0.7599 | D29: 1 | F29: NORMA. Bonus to'liq.
B30: 0.76 | C30: 0.8599 | D30: 1.15 | F30: Normadan yuqori.
B31: 0.86 | C31: 1 | D31: 1.25 | F31: Zo'r natija.
A32: E. SAMARADORLIK KOEFFITSIENTI — vazifalarni o'z vaqtida bajarish (butun bonusga)
B33: Quyi chegara | C33: Yuqori chegara | D33: KOEFFITSIENT | F33: Izoh
B34: 0 | C34: 0.7999 | D34: 0.75 | F34: Intizom yo'q.
B35: 0.8 | C35: 0.8999 | D35: 0.9 | F35: Yetarli emas.
B36: 0.9 | C36: 0.9499 | D36: 1 | F36: NORMA.
B37: 0.95 | C37: 1 | D37: 1.05 | F37: Namunali xodim.
A38: F. TUZATUVCHI QOIDALAR
B39: «Uzaytirish» ta'rifi | C39: Uzaytirish = kursni tugatib boshqa kursda o'qishni boshlasa, o'quvchi keyingi bosqichga o'tishi va shartnoma yangilanishi. Oddiy oylik to'lov uzaytirish HISOBLANMAYDI. Bu ta'rifni buzish butun tizimni qimmatlashtiradi va oy oxirida bahs keltirib chiqaradi.
B40: Ketish sababi - 100% majburiy | C40: Har bir ketgan o'quvchi uchun CRMda aniq sabab: narx · jadval mos emas · o'qituvchi · natija ko'rinmadi · ko'chib ketdi · sog'liq · boshqa markazga o'tdi. «Noma'lum» tanlansa — jarima. Sabab bilinmasa, sabab bartaraf ham etilmaydi.
B41: Nazoratdan tashqari holatlar | C41: Ko'chib ketish, sog'liq, oilaviy sharoit - ketish foizidan CHIQARILADI. Adminni o'zi ta'sir qila olmaydigan narsa uchun jazolamaymiz.
B42: Bonus A - faqat HAQIQIY faol o'quvchi | C42: Oy oxirida darsga qatnashayotgan va to'lovi joyida bo'lgan o'quvchilar. 30 kundan ortiq kelmagan yoki 45 kundan ortiq qarzi bor o'quvchi «faol» hisoblanmaydi. Aks holda raqam sun'iy oshiriladi
B43: Qarzdorlik bonusi sharti | C43: Yig'ish foizi 80% dan past bo'lsa bonus foizi yarmiga tushadi (1% - 0.5%) bu 10 sanadan keyin undirilgan summaning foizdan bonus qilib beriladi
B44: Tiket sabablari | C44: Xona nazorati o'tkazilmadi, kelmagan o'quvchiga xabar yuborilmadi, qarzdorga aloqaga chiqilmadi, ketish sababi yozilmadi, kutish zonasi tartibsiz, o'qituvchi so'rovi 2 kundan ortiq javobsiz qoldi.
...

Sheet KALKULYATOR
A1: OYLIK KALKULYATORI Sariq yacheykalarga oy oxiridagi HAQIQIY raqamlarni kiritish kerak
A5: OY OXIRIDAGI HAQIQIY RAQAMLAR
B6: Oy BOSHIDAGI faol o'quvchi soni | C6: 500 | D6: LMS ma'lumot
B7: Oy davomida ketgan (nazoratdagi sabablar) | C7: 60
B8: Oy OXIRIDAGI faol o'quvchi soni | C8: 440 | D8: Yangi qo'shilganlar bilan birga. BONUS A shundan hisoblanadi.
B9: Kursi tugagan o'quvchi soni | C9: 40 | D9: Shu oyda bosqichni tamomlaganlar.
B10: Ulardan keyingi bosqichga o'tganlar | C10: 29 | D10: BONUS B shundan.
B11: Oy boshidagi qarzdorlik summasi | C11: 18000000
B12: Oy davomida yig'ilgan qarz summasi | C12: 79000000 | D12: BONUS C shundan.
B13: Samaradorlik — vazifalar o'z vaqtida | C13: 0.93 | D13: amoCRM hisoboti.
B14: Sababi aniqlanmagan ketishlar soni | C14: 0
B15: Tiket soni | C15: 1
A16: KO'RSATKICHLAR (avtomatik)
B17: Ketish foizi (otток) | C17: =IF(C6=0,0,C7/C6) -> 0.12 | D17: Norma: 6–8%.
B18: Uzaytirish konversiyasi | C18: =IF(C9=0,0,C10/C9) -> 0.725 | D18: Norma: 65–76%.
B19: Qarzdorlik yig'ilishi | C19: =IF(C11=0,0,C12/C11) -> 4.3888889 | D19: Norma: 80% dan yuqori.
A20: KOEFFITSIENTLAR (avtomatik)
B21: Ushlab qolish koeffitsienti | C21: =INDEX('KPI qoidalari'!$D$19:$D$24,MATCH(C17,'KPI qoidalari'!$B$19:$B$24,1)) -> 0.4 | D21: Ketish foizi bo'yicha, C-jadval.
B22: Uzaytirish koeffitsienti | C22: =INDEX('KPI qoidalari'!$D$27:$D$31,MATCH(C18,'KPI qoidalari'!$B$27:$B$31,1)) -> 1 | D22: D-jadval.
B23: Samaradorlik koeffitsienti | C23: =INDEX('KPI qoidalari'!$D$34:$D$37,MATCH(C13,'KPI qoidalari'!$B$34:$B$37,1)) -> 1 | D23: E-jadval.
B24: Qarzdorlik bonus foizi | C24: =IF(C19>=0.8,'KPI qoidalari'!$C$12,'KPI qoidalari'!$C$12/2) -> 0.01 | D24: Yig'ish 80% dan past bo'lsa — yarmi.
A25: OYLIK HISOBI
B26: Oklad | C26: ='KPI qoidalari'!$C$9 -> 3000000 | D26: O'zgarmas.
B27: BONUS A — ushlab qolish | C27: =C8*'KPI qoidalari'!$C$10*C21 -> 176000 | D27: Faol o'quvchi × 6 000 × koeffitsient.
B28: BONUS B — uzaytirish | C28: =C10*'KPI qoidalari'!$C$11*C22 -> 1015000 | D28: Uzaytirgan × 45 000 × koeffitsient.
B29: BONUS C — qarzdorlik | C29: =C12*C24 -> 790000 | D29: Yig'ilgan summaning foizi.
B30: Jami bonus × samaradorlik | C30: =(C27+C28+C29)*C23 -> 1981000 | D30: Samaradorlik butun bonusni ko'paytiradi.
B31: Jarima — sababi aniqlanmagan ketish | C31: =-C14*'KPI qoidalari'!$C$13 -> 0
B32: Jarima — tiketlar | C32: =-C15*'KPI qoidalari'!$C$14 -> -50000
B33: HISOBLANGAN OYLIK | C33: =C26+C30+C31+C32 -> 4931000 | D33: Oklad + bonus − jarimalar.
B34: Kafolat bilan (faqat 1–2 oy) | C34: =MAX(C33,'KPI qoidalari'!$C$15) -> 4931000 | D34: Kalibrovka davrida to'lanadigan summa.

Sheet Ssenariylar
A1: 6 XIL OY — CHIQUVCHI ADMIN QANCHA OLADI Ko'k raqamlarni o'zgartirib ko'rishingiz mumkin. Jarimalar bu jadvalda hisobga olinmagan.
B5: Ssenariy | C5: Boshida faol | D5: Ketgan | E5: Oxirida faol | F5: Kursi tugagan | G5: Uzay- tirgan | H5: Yig'ilgan qarz | I5: Samarador- lik | J5: Ketish % | K5: Uzaytirish % | L5: Bonus A | M5: Bonus B | N5: JAMI OYLIK | O5: Izoh
B6: Zaif oy | C6: 320 | D6: 42 | E6: 300 | F6: 38 | G6: 19 | H6: 9000000 | I6: 0.88 | J6: =D6/C6 -> 0.13125 | K6: =G6/F6 -> 0.5 | L6: =E6*'KPI qoidalari'!$C$10*INDEX('KPI qoidalari'!$D$19:$D$24,MATCH(J6,'KPI qoidalari'!$B$19:$B$24,1)) -> 120000 | M6: =G6*'KPI qoidalari'!$C$11*INDEX('KPI qoidalari'!$D$27:$D$31,MATCH(K6,'KPI qoidalari'!$B$27:$B$31,1)) -> 332500 | N6: ='KPI qoidalari'!$C$9+(L6+M6+H6*'KPI qoidalari'!$C$12)*INDEX('KPI qoidalari'!$D$34:$D$37,MATCH(I6,'KPI qoidalari'!$B$34:$B$37,1)) -> 3488250 | O6: Ketish 13%, uzaytirish 50%. Kafolat ishlaydi.
B7: Normadan past | C7: 320 | D7: 30 | E7: 315 | F7: 40 | G7: 25 | H7: 13000000 | I7: 0.91 | J7: =D7/C7 -> 0.09375 | K7: =G7/F7 -> 0.625 | L7: =E7*'KPI qoidalari'!$C$10*INDEX('KPI qoidalari'!$D$19:$D$24,MATCH(J7,'KPI qoidalari'!$B$19:$B$24,1)) -> 252000 | M7: =G7*'KPI qoidalari'!$C$11*INDEX('KPI qoidalari'!$D$27:$D$31,MATCH(K7,'KPI qoidalari'!$B$27:$B$31,1)) -> 700000 | N7: ='KPI qoidalari'!$C$9+(L7+M7+H7*'KPI qoidalari'!$C$12)*INDEX('KPI qoidalari'!$D$34:$D$37,MATCH(I7,'KPI qoidalari'!$B$34:$B$37,1)) -> 4082000 | O7: Ketish 9.4% - koeffitsient 0.80 ga tushdi.
B8: NORMA | C8: 320 | D8: 22 | E8: 330 | F8: 40 | G8: 29 | H8: 15500000 | I8: 0.93 | J8: =D8/C8 -> 0.06875 | K8: =G8/F8 -> 0.725 | L8: =E8*'KPI qoidalari'!$C$10*INDEX('KPI qoidalari'!$D$19:$D$24,MATCH(J8,'KPI qoidalari'!$B$19:$B$24,1)) -> 330000 | M8: =G8*'KPI qoidalari'!$C$11*INDEX('KPI qoidalari'!$D$27:$D$31,MATCH(K8,'KPI qoidalari'!$B$27:$B$31,1)) -> 1015000 | N8: ='KPI qoidalari'!$C$9+(L8+M8+H8*'KPI qoidalari'!$C$12)*INDEX('KPI qoidalari'!$D$34:$D$37,MATCH(I8,'KPI qoidalari'!$B$34:$B$37,1)) -> 4500000 | O8: Bizdan kutilayotgan barqaror oy.
B9: Yaxshi oy | C9: 325 | D9: 17 | E9: 340 | F9: 44 | G9: 35 | H9: 17000000 | I9: 0.95 | J9: =D9/C9 -> 0.052307692 | K9: =G9/F9 -> 0.79545455 | L9: =E9*'KPI qoidalari'!$C$10*INDEX('KPI qoidalari'!$D$19:$D$24,MATCH(J9,'KPI qoidalari'!$B$19:$B$24,1)) -> 374000 | M9: =G9*'KPI qoidalari'!$C$11*INDEX('KPI qoidalari'!$D$27:$D$31,MATCH(K9,'KPI qoidalari'!$B$27:$B$31,1)) -> 1408750 | N9: ='KPI qoidalari'!$C$9+(L9+M9+H9*'KPI qoidalari'!$C$12)*INDEX('KPI qoidalari'!$D$34:$D$37,MATCH(I9,'KPI qoidalari'!$B$34:$B$37,1)) -> 5050387.5 | O9: Ketish 5.2%, uzaytirish 79.5%.
B10: Kuchli oy | C10: 500 | D10: 30 | E10: 440 | F10: 44 | G10: 38 | H10: 70000000 | I10: 0.96 | J10: =D10/C10 -> 0.06 | K10: =G10/F10 -> 0.86363636 | L10: =E10*'KPI qoidalari'!$C$10*INDEX('KPI qoidalari'!$D$19:$D$24,MATCH(J10,'KPI qoidalari'!$B$19:$B$24,1)) -> 440000 | M10: =G10*'KPI qoidalari'!$C$11*INDEX('KPI qoidalari'!$D$27:$D$31,MATCH(K10,'KPI qoidalari'!$B$27:$B$31,1)) -> 1662500 | N10: ='KPI qoidalari'!$C$9+(L10+M10+H10*'KPI qoidalari'!$C$12)*INDEX('KPI qoidalari'!$D$34:$D$37,MATCH(I10,'KPI qoidalari'!$B$34:$B$37,1)) -> 5942625 | O10: Ketish 3.6%, uzaytirish 86.4%.
B11: Uzaytirdi, USHLAB QOLMADI | C11: 330 | D11: 46 | E11: 320 | F11: 44 | G11: 38 | H11: 16000000 | I11: 0.92 | J11: =D11/C11 -> 0.13939394 | K11: =G11/F11 -> 0.86363636 | L11: =E11*'KPI qoidalari'!$C$10*INDEX('KPI qoidalari'!$D$19:$D$24,MATCH(J11,'KPI qoidalari'!$B$19:$B$24,1)) -> 128000 | M11: =G11*'KPI qoidalari'!$C$11*INDEX('KPI qoidalari'!$D$27:$D$31,MATCH(K11,'KPI qoidalari'!$B$27:$B$31,1)) -> 1662500 | N11: ='KPI qoidalari'!$C$9+(L11+M11+H11*'KPI qoidalari'!$C$12)*INDEX('KPI qoidalari'!$D$34:$D$37,MATCH(I11,'KPI qoidalari'!$B$34:$B$37,1)) -> 4950500 | O11: Uzaytirish 86% - zo'r. Lekin ketish 13.9%.
B12: SHU JADVALDAN CHIQADIGAN XULOSA
B13: • Oxirgi qator: admin uzaytirishda zo'r ishlagan (86%), lekin 46 ta o'quvchi kurs O'RTASIDA ketib qolgan. Bonus A koeffitsienti 0.40 ga tushadi va u «Yaxshi oy» adminidan sezilarli kam oladi.
B14: • Bonus A bonusning eng katta qismi — bu ataylab shunday. Chiquvchi adminning asosiy ishi oy oxiridagi uzaytirish qo'ng'irog'i emas, kundalik davomad va muammoni erta ko'rish.
B15: • Zaif oyda hisoblangan summa kafolatlangan minimumdan past chiqadi — birinchi 2 oyda kafolat ishlaydi.

Sheet Birli iqtisodiyoti
A1: BIRLIK IQTISODIYOTI — TEKSHIRUV HISOBI Bonus markaz marginidan qancha ulush olayotganini ko'rsatadi. Sariq yacheykalarni o'zimi to'ldiramiz
A5: BOSHLANG'ICH RAQAMLAR
B6: Kurs narxi (1 oy, 1 o'quvchi) | C6: 500000 | E6: Sentyabrdan.
B7: O'qituvchi ulushi | C7: 0.55 | E7: 50/50 va 60/40 orasidagi o'rtacha.
B8: Markazga qoladigan margin (1 o'quvchi / 1 oy) | C8: =C6*(1-C7) -> 225000 | E8: O'qituvchidan keyingi summa. Ijara, marketing, oyliklar shundan chiqadi.
B9: Oy oxiridagi faol o'quvchi soni | C9: 330 | E9: 3_KALKULYATOR bilan bir xil bo'lsin.
B10: MARKAZNING OYLIK MARGINI | C10: =C8*C9 -> 74250000 | E10: Barcha xarajatlar shundan qoplanadi.
A11: BONUS ULUSHI
B12: Bonus A - 1 o'quvchi uchun | C12: ='KPI qoidalari'!$C$10 -> 1000 | E12: Doimiy qiymat.
B13: Bonus A 1 o'quvchi marginidan ulushi | C13: =C12/C8 -> 0.0044444444 | E13: 3% dan past bo'lsa — sog'lom.
B14: Bonus B - 1 uzaytirish uchun | C14: ='KPI qoidalari'!$C$11 -> 35000
B15: Uzaytirish qancha oylik daromad keltiradi | C15: 4 | E15: Keyingi bosqich necha oy davom etadi.
B16: 1 uzaytirish keltiradigan margin | C16: =C8*C15 -> 900000
B17: Bonus B shu margindan ulushi | C17: =C14/C16 -> 0.038888889 | E17: 5% dan past bo'lsa — sog'lom.
B18: Chiquvchi admin oyligi (NORMA) | C18: =KALKULYATOR!C33 -> 4931000 | E18: Kalkulyatordan olinadi.
B19: Oylik markaz marginidan ulushi | C19: =C18/C10 -> 0.066410774 | E19: 10% dan past bo'lsa — sog'lom.
A20: QANDAY O'QISH KERAK
B21: Agar 20-qator 10% dan oshsa | C21: Chiquvchi admin markaz marginining juda katta qismini olyapti. Ikkita yo'l bor: yo faol o'quvchi sonini oshirish, yo Bonus A dagi 1 000 so'mni pasaytirish.
B22: Agar 14-qator 3% dan oshsa | C22: 1 o'quvchiga to'g'ri keladigan bonus qimmat. Bu odatda faol o'quvchi soni kam bo'lganda emas, balki margin past bo'lganda (o'qituvchi ulushi yuqori) yuz beradi.
B23: Agar 18-qator 5% dan oshsa | C23: Uzaytirish bonusi qimmat. Lekin avval 16-qatorni tekshiring: agar keyingi bosqich 4 oy emas, 2 oy bo'lsa, bonus haqiqatan ham baland.
B24: Ikkala admin birgalikda | C24: Kiruvchi (6–7 mln) + chiquvchi (6–7 mln) = 12–14 mln. Bu margin­ning 20% idan oshmasligi kerak. Ya'ni markaz oylik margini kamida 60–70 mln bo'lishi lozim — bu taxminan 270–310 ta faol o'quvchi degani.

Sheet Vazifa va KPI
A1: HAR BIR VAZIFA QAYSI KPI'GA ULANADI Hech bir vazifa «shunchaki bajariladi» bo'lmasin - har biri o'lchanadigan natijaga ulanadi.
A5: № | B5: Kundalik vazifa | C5: Qaysi KPI'ga ta'sir qiladi | D5: Audit mezoni | E5: Nega aynan shunday
A6: 1 | B6: Kunlik davomad nazorati | C6: BONUS A (ushlab qolish) | D6: - | E6: Ketish birdan bo'lmaydi. Odam avval 2–3 dars qoldiradi. Davomad - erta ogohlantirish tizimi
A7: 2 | B7: Kelmagan o'quvchiga o'sha kuni xabar | C7: BONUS A | D7: - | E7: 24 soatdan keyingi xabarning ta'siri keskin kamayadi.
A8: 3 | B8: Ketish sababini aniqlash | C8: Jarima (aniqlanmagan sabab) | D8: - | E8: Sabab bilinmasa, bartaraf ham etilmaydi. Bu ma'lumot marketing va o'qituvchilar uchun ham kerak.
A9: 4 | B9: Kurs tugayotgan guruhlar bilan ishlash | C9: BONUS B (uzaytirish) | D9: - | E9: Kurs tugashidan 3 hafta oldin boshlanadi, oxirgi kuni emas.
A10: 5 | B10: Qarzdorlarga aloqaga chiqish | C10: BONUS C | D10: - | E10: Qarz eskirgan sari yig'ilish ehtimoli pasayadi.
A11: 6 | B11: Har kuni xona va texnika nazorati | C11: Tiket | D11: 10-mezon (bizda 0 ball) | E11: Auditda bino va xona holati bo'yicha 0 ball olganmiz. Faqat kundalik nazorat bilan ko'tariladi.
A12: 7 | B12: Kutish zonasi tartibi | C12: Tiket | D12: 11-mezon (bizda 2 ball) | E12: Bizning kam sonli ustunligimiz. Saqlab qolish kerak.
A13: 8 | B13: Devordagi natijalar taxtasi | C13: Tiket | D13: 12-mezon (bizda 0 ball) | E13: Marketing tayyorlaydi, chiquvchi admin joyida yangilab turadi.
A14: 9 | B14: O'qituvchi so'rovlari (material, jihoz) | C14: Tiket - BONUS A | D14: - | E14: O'qituvchi noroziligi bevosita o'quvchi ketishiga aylanadi.
A15: 10 | B15: CRM gigiyenasi | C15: Samaradorlik koeffitsienti | D15: - | E15: Butun bonusni ko'paytiradi yoki kamaytiradi.
